{"uuid": "8a24a43b-f72b-4750-a8cd-39cc97600bde", "children": ["635ba772-5ee3-4208-aac5-2ad26674f077"], "befores": [{"name": "chrome_driver", "status": "broken", "statusDetails": {"message": "selenium.common.exceptions.WebDriverException: Message: 'chromedriver' executable needs to be in PATH. Please see https://sites.google.com/a/chromium.org/chromedriver/home\n\n", "trace": "  File \"/Users/gevfolder/venv/lib/python3.8/site-packages/pluggy/callers.py\", line 187, in _multicall\n    res = hook_impl.function(*args)\n  File \"/Users/gevfolder/venv/lib/python3.8/site-packages/_pytest/fixtures.py\", line 957, in pytest_fixture_setup\n    result = call_fixture_func(fixturefunc, request, kwargs)\n  File \"/Users/gevfolder/venv/lib/python3.8/site-packages/_pytest/fixtures.py\", line 783, in call_fixture_func\n    res = next(it)\n  File \"/Users/gevfolder/PycharmProjects/autotests/tests/conftest.py\", line 7, in chrome_driver\n    driver = webdriver.Chrome(executable_path=\"../../drivers/chromedriver\")\n  File \"/Users/gevfolder/venv/lib/python3.8/site-packages/selenium/webdriver/chrome/webdriver.py\", line 73, in __init__\n    self.service.start()\n  File \"/Users/gevfolder/venv/lib/python3.8/site-packages/selenium/webdriver/common/service.py\", line 81, in start\n    raise WebDriverException(\n"}, "start": 1576257242402, "stop": 1576257242405}], "start": 1576257242402, "stop": 1576257242612}