{"uuid": "751e19e6-010c-4601-ac05-cd4bb3ff9577", "children": ["7cf79f76-4e7b-4b16-9bca-bb1b262cc390"], "befores": [{"name": "chrome_driver", "status": "broken", "statusDetails": {"message": "selenium.common.exceptions.WebDriverException: Message: 'chromedriver' executable needs to be in PATH. Please see https://sites.google.com/a/chromium.org/chromedriver/home\n\n", "trace": "  File \"/Users/gevfolder/venv/lib/python3.8/site-packages/pluggy/callers.py\", line 187, in _multicall\n    res = hook_impl.function(*args)\n  File \"/Users/gevfolder/venv/lib/python3.8/site-packages/_pytest/fixtures.py\", line 957, in pytest_fixture_setup\n    result = call_fixture_func(fixturefunc, request, kwargs)\n  File \"/Users/gevfolder/venv/lib/python3.8/site-packages/_pytest/fixtures.py\", line 783, in call_fixture_func\n    res = next(it)\n  File \"/Users/gevfolder/PycharmProjects/autotests/tests/conftest.py\", line 7, in chrome_driver\n    driver = webdriver.Chrome(executable_path=\"../../../drivers/chromedriver\")\n  File \"/Users/gevfolder/venv/lib/python3.8/site-packages/selenium/webdriver/chrome/webdriver.py\", line 73, in __init__\n    self.service.start()\n  File \"/Users/gevfolder/venv/lib/python3.8/site-packages/selenium/webdriver/common/service.py\", line 81, in start\n    raise WebDriverException(\n"}, "start": 1576257281975, "stop": 1576257281978}], "start": 1576257281975, "stop": 1576257282189}